Workbook

Sheet DailyActivity
A1: Id | B1: ActivityDate | C1: TotalSteps | D1: TotalDistance | E1: TrackerDistance | F1: LoggedActivitiesDistance | G1: VeryActiveDistance | H1: ModeratelyActiveDistance | I1: LightActiveDistance | J1: SedentaryActiveDistance | K1: VeryActiveMinutes | L1: FairlyActiveMinutes | M1: LightlyActiveMinutes | N1: SedentaryMinutes | O1: Calories
A2: 1503960366 | B2: 42472 | C2: 13162 | D2: 8.5 | E2: 8.5 | F2: 0 | G2: 1.88 | H2: 0.55000001 | I2: 6.0599999 | J2: 0 | K2: 25 | L2: 13 | M2: 328 | N2: 728 | O2: 1985
A3: 1503960366 | B3: 42473 | C3: 10735 | D3: 6.9699998 | E3: 6.9699998 | F3: 0 | G3: 1.5700001 | H3: 0.69 | I3: 4.71 | J3: 0 | K3: 21 | L3: 19 | M3: 217 | N3: 776 | O3: 1797
A4: 1503960366 | B4: 42474 | C4: 10460 | D4: 6.7399998 | E4: 6.7399998 | F4: 0 | G4: 2.4400001 | H4: 0.40000001 | I4: 3.9100001 | J4: 0 | K4: 30 | L4: 11 | M4: 181 | N4: 1218 | O4: 1776
A5: 1503960366 | B5: 42475 | C5: 9762 | D5: 6.2800002 | E5: 6.2800002 | F5: 0 | G5: 2.1400001 | H5: 1.26 | I5: 2.8299999 | J5: 0 | K5: 29 | L5: 34 | M5: 209 | N5: 726 | O5: 1745
A6: 1503960366 | B6: 42476 | C6: 12669 | D6: 8.1599998 | E6: 8.1599998 | F6: 0 | G6: 2.71 | H6: 0.41 | I6: 5.04 | J6: 0 | K6: 36 | L6: 10 | M6: 221 | N6: 773 | O6: 1863
A7: 1503960366 | B7: 42477 | C7: 9705 | D7: 6.48 | E7: 6.48 | F7: 0 | G7: 3.1900001 | H7: 0.77999997 | I7: 2.51 | J7: 0 | K7: 38 | L7: 20 | M7: 164 | N7: 539 | O7: 1728
A8: 1503960366 | B8: 42478 | C8: 13019 | D8: 8.5900002 | E8: 8.5900002 | F8: 0 | G8: 3.25 | H8: 0.63999999 | I8: 4.71 | J8: 0 | K8: 42 | L8: 16 | M8: 233 | N8: 1149 | O8: 1921
A9: 1503960366 | B9: 42479 | C9: 15506 | D9: 9.8800001 | E9: 9.8800001 | F9: 0 | G9: 3.53 | H9: 1.3200001 | I9: 5.0300002 | J9: 0 | K9: 50 | L9: 31 | M9: 264 | N9: 775 | O9: 2035
A10: 1503960366 | B10: 42480 | C10: 10544 | D10: 6.6799998 | E10: 6.6799998 | F10: 0 | G10: 1.96 | H10: 0.47999999 | I10: 4.2399998 | J10: 0 | K10: 28 | L10: 12 | M10: 205 | N10: 818 | O10: 1786
A11: 1503960366 | B11: 42481 | C11: 9819 | D11: 6.3400002 | E11: 6.3400002 | F11: 0 | G11: 1.34 | H11: 0.34999999 | I11: 4.6500001 | J11: 0 | K11: 19 | L11: 8 | M11: 211 | N11: 838 | O11: 1775
A12: 1503960366 | B12: 42482 | C12: 12764 | D12: 8.1300001 | E12: 8.1300001 | F12: 0 | G12: 4.7600002 | H12: 1.12 | I12: 2.24 | J12: 0 | K12: 66 | L12: 27 | M12: 130 | N12: 1217 | O12: 1827
A13: 1503960366 | B13: 42483 | C13: 14371 | D13: 9.04 | E13: 9.04 | F13: 0 | G13: 2.8099999 | H13: 0.87 | I13: 5.3600001 | J13: 0 | K13: 41 | L13: 21 | M13: 262 | N13: 732 | O13: 1949
... A941: 8877689391 | B941: 42502 | C941: 8064 | D941: 6.1199999 | E941: 6.1199999 | F941: 0 | G941: 1.8200001 | H941: 0.039999999 | I941: 4.25 | J941: 0 | K941: 23 | L941: 1 | M941: 137 | N941: 770 | O941: 1849

Sheet Sleep
A1: Id | B1: SleepDay | C1: Uniqe ID | D1: TotalSleepRecords | E1: TotalMinutesAsleep | F1: TotalHoursAsleep | G1: TotalTimeInBed | H1: TotalHoursInBed | I1: Efektywność snu | J1: QualityOfSleep
A2: 1503960366 | B2: 42472 | C2: =CONCAT(A2,B2) -> 150396036642472 | D2: 1 | E2: 327 | F2: =E2/1440 -> 0.22708333 | G2: 346 | H2: =G2/1440 -> 0.24027778 | I2: =E2/G2 -> 0.94508671 | J2: =IF(E2<360, "LOW",IF(E2<480, "OK","HIGH")) -> LOW
A3: 1503960366 | B3: 42473 | C3: =CONCAT(A3,B3) -> 150396036642473 | D3: 2 | E3: 384 | F3: =E3/1440 -> 0.26666667 | G3: 407 | H3: =G3/1440 -> 0.28263889 | I3: =E3/G3 -> 0.94348894 | J3: =IF(E3<360, "LOW",IF(E3<480, "OK","HIGH")) -> OK
A4: 1503960366 | B4: 42475 | C4: =CONCAT(A4,B4) -> 150396036642475 | D4: 1 | E4: 412 | F4: =E4/1440 -> 0.28611111 | G4: 442 | H4: =G4/1440 -> 0.30694444 | I4: =E4/G4 -> 0.9321267 | J4: =IF(E4<360, "LOW",IF(E4<480, "OK","HIGH")) -> OK
A5: 1503960366 | B5: 42476 | C5: =CONCAT(A5,B5) -> 150396036642476 | D5: 2 | E5: 340 | F5: =E5/1440 -> 0.23611111 | G5: 367 | H5: =G5/1440 -> 0.25486111 | I5: =E5/G5 -> 0.92643052 | J5: =IF(E5<360, "LOW",IF(E5<480, "OK","HIGH")) -> LOW
A6: 1503960366 | B6: 42477 | C6: =CONCAT(A6,B6) -> 150396036642477 | D6: 1 | E6: 700 | F6: =E6/1440 -> 0.48611111 | G6: 712 | H6: =G6/1440 -> 0.49444444 | I6: =E6/G6 -> 0.98314607 | J6: =IF(E6<360, "LOW",IF(E6<480, "OK","HIGH")) -> HIGH
A7: 1503960366 | B7: 42479 | C7: =CONCAT(A7,B7) -> 150396036642479 | D7: 1 | E7: 304 | F7: =E7/1440 -> 0.21111111 | G7: 320 | H7: =G7/1440 -> 0.22222222 | I7: =E7/G7 -> 0.95 | J7: =IF(E7<360, "LOW",IF(E7<480, "OK","HIGH")) -> LOW
A8: 1503960366 | B8: 42480 | C8: =CONCAT(A8,B8) -> 150396036642480 | D8: 1 | E8: 360 | F8: =E8/1440 -> 0.25 | G8: 377 | H8: =G8/1440 -> 0.26180556 | I8: =E8/G8 -> 0.95490716 | J8: =IF(E8<360, "LOW",IF(E8<480, "OK","HIGH")) -> OK
A9: 1503960366 | B9: 42481 | C9: =CONCAT(A9,B9) -> 150396036642481 | D9: 1 | E9: 325 | F9: =E9/1440 -> 0.22569444 | G9: 364 | H9: =G9/1440 -> 0.25277778 | I9: =E9/G9 -> 0.89285714 | J9: =IF(E9<360, "LOW",IF(E9<480, "OK","HIGH")) -> LOW
A10: 1503960366 | B10: 42483 | C10: =CONCAT(A10,B10) -> 150396036642483 | D10: 1 | E10: 361 | F10: =E10/1440 -> 0.25069444 | G10: 384 | H10: =G10/1440 -> 0.26666667 | I10: =E10/G10 -> 0.94010417 | J10: =IF(E10<360, "LOW",IF(E10<480, "OK","HIGH")) -> OK
A11: 1503960366 | B11: 42484 | C11: =CONCAT(A11,B11) -> 150396036642484 | D11: 1 | E11: 430 | F11: =E11/1440 -> 0.29861111 | G11: 449 | H11: =G11/1440 -> 0.31180556 | I11: =E11/G11 -> 0.95768374 | J11: =IF(E11<360, "LOW",IF(E11<480, "OK","HIGH")) -> OK
A12: 1503960366 | B12: 42485 | C12: =CONCAT(A12,B12) -> 150396036642485 | D12: 1 | E12: 277 | F12: =E12/1440 -> 0.19236111 | G12: 323 | H12: =G12/1440 -> 0.22430556 | I12: =E12/G12 -> 0.85758514 | J12: =IF(E12<360, "LOW",IF(E12<480, "OK","HIGH")) -> LOW
A13: 1503960366 | B13: 42486 | C13: =CONCAT(A13,B13) -> 150396036642486 | D13: 1 | E13: 245 | F13: =E13/1440 -> 0.17013889 | G13: 274 | H13: =G13/1440 -> 0.19027778 | I13: =E13/G13 -> 0.89416058 | J13: =IF(E13<360, "LOW",IF(E13<480, "OK","HIGH")) -> LOW
... A414: 8792009665 | B414: 42494 | C414: =CONCAT(A414,B414) -> 879200966542494 | D414: 1 | E414: 439 | F414: =E414/1440 -> 0.30486111 | G414: 463 | H414: =G414/1440 -> 0.32152778 | I414: =E414/G414 -> 0.94816415 | J414: =IF(E414<360, "LOW",IF(E414<480, "OK","HIGH")) -> OK

Sheet Activity
D1: Activity Level | E1: Activity days
D2: =IF(B2<5000, "LOW",IF(B2<10000,"MEDIUM","HIGH")) -> HIGH | E2: =IFERROR(__xludf.DUMMYFUNCTION("COUNTUNIQUEIFS(DailyActivity!B:B,DailyActivity!A:A,A2)"),31.0) -> 31
D3: =IF(B3<5000, "LOW",IF(B3<10000,"MEDIUM","HIGH")) -> MEDIUM | E3: =IFERROR(__xludf.DUMMYFUNCTION("COUNTUNIQUEIFS(DailyActivity!B:B,DailyActivity!A:A,A3)"),31.0) -> 31
D4: =IF(B4<5000, "LOW",IF(B4<10000,"MEDIUM","HIGH")) -> MEDIUM | E4: =IFERROR(__xludf.DUMMYFUNCTION("COUNTUNIQUEIFS(DailyActivity!B:B,DailyActivity!A:A,A4)"),30.0) -> 30
D5: =IF(B5<5000, "LOW",IF(B5<10000,"MEDIUM","HIGH")) -> LOW | E5: =IFERROR(__xludf.DUMMYFUNCTION("COUNTUNIQUEIFS(DailyActivity!B:B,DailyActivity!A:A,A5)"),31.0) -> 31
D6: =IF(B6<5000, "LOW",IF(B6<10000,"MEDIUM","HIGH")) -> LOW | E6: =IFERROR(__xludf.DUMMYFUNCTION("COUNTUNIQUEIFS(DailyActivity!B:B,DailyActivity!A:A,A6)"),31.0) -> 31
D7: =IF(B7<5000, "LOW",IF(B7<10000,"MEDIUM","HIGH")) -> HIGH | E7: =IFERROR(__xludf.DUMMYFUNCTION("COUNTUNIQUEIFS(DailyActivity!B:B,DailyActivity!A:A,A7)"),31.0) -> 31
D8: =IF(B8<5000, "LOW",IF(B8<10000,"MEDIUM","HIGH")) -> MEDIUM | E8: =IFERROR(__xludf.DUMMYFUNCTION("COUNTUNIQUEIFS(DailyActivity!B:B,DailyActivity!A:A,A8)"),31.0) -> 31
D9: =IF(B9<5000, "LOW",IF(B9<10000,"MEDIUM","HIGH")) -> LOW | E9: =IFERROR(__xludf.DUMMYFUNCTION("COUNTUNIQUEIFS(DailyActivity!B:B,DailyActivity!A:A,A9)"),31.0) -> 31
D10: =IF(B10<5000, "LOW",IF(B10<10000,"MEDIUM","HIGH")) -> MEDIUM | E10: =IFERROR(__xludf.DUMMYFUNCTION("COUNTUNIQUEIFS(DailyActivity!B:B,DailyActivity!A:A,A10)"),18.0) -> 18
D11: =IF(B11<5000, "LOW",IF(B11<10000,"MEDIUM","HIGH")) -> MEDIUM | E11: =IFERROR(__xludf.DUMMYFUNCTION("COUNTUNIQUEIFS(DailyActivity!B:B,DailyActivity!A:A,A11)"),31.0) -> 31
D12: =IF(B12<5000, "LOW",IF(B12<10000,"MEDIUM","HIGH")) -> MEDIUM | E12: =IFERROR(__xludf.DUMMYFUNCTION("COUNTUNIQUEIFS(DailyActivity!B:B,DailyActivity!A:A,A12)"),20.0) -> 20
D13: =IF(B13<5000, "LOW",IF(B13<10000,"MEDIUM","HIGH")) -> HIGH | E13: =IFERROR(__xludf.DUMMYFUNCTION("COUNTUNIQUEIFS(DailyActivity!B:B,DailyActivity!A:A,A13)"),30.0) -> 30
D14: =IF(B14<5000, "LOW",IF(B14<10000,"MEDIUM","HIGH")) -> LOW | E14: =IFERROR(__xludf.DUMMYFUNCTION("COUNTUNIQUEIFS(DailyActivity!B:B,DailyActivity!A:A,A14)"),31.0) -> 31
D15: =IF(B15<5000, "LOW",IF(B15<10000,"MEDIUM","HIGH")) -> LOW | E15: =IFERROR(__xludf.DUMMYFUNCTION("COUNTUNIQUEIFS(DailyActivity!B:B,DailyActivity!A:A,A15)"),4.0) -> 4
D16: =IF(B16<5000, "LOW",IF(B16<10000,"MEDIUM","HIGH")) -> MEDIUM | E16: =IFERROR(__xludf.DUMMYFUNCTION("COUNTUNIQUEIFS(DailyActivity!B:B,DailyActivity!A:A,A16)"),31.0) -> 31
D17: =IF(B17<5000, "LOW",IF(B17<10000,"MEDIUM","HIGH")) -> HIGH | E17: =IFERROR(__xludf.DUMMYFUNCTION("COUNTUNIQUEIFS(DailyActivity!B:B,DailyActivity!A:A,A17)"),31.0) -> 31
D18: =IF(B18<5000, "LOW",IF(B18<10000,"MEDIUM","HIGH")) -> LOW | E18: =IFERROR(__xludf.DUMMYFUNCTION("COUNTUNIQUEIFS(DailyActivity!B:B,DailyActivity!A:A,A18)"),31.0) -> 31
D19: =IF(B19<5000, "LOW",IF(B19<10000,"MEDIUM","HIGH")) -> MEDIUM | E19: =IFERROR(__xludf.DUMMYFUNCTION("COUNTUNIQUEIFS(DailyActivity!B:B,DailyActivity!A:A,A19)"),31.0) -> 31
D20: =IF(B20<5000, "LOW",IF(B20<10000,"MEDIUM","HIGH")) -> MEDIUM | E20: =IFERROR(__xludf.DUMMYFUNCTION("COUNTUNIQUEIFS(DailyActivity!B:B,DailyActivity!A:A,A20)"),31.0) -> 31
D21: =IF(B21<5000, "LOW",IF(B21<10000,"MEDIUM","HIGH")) -> MEDIUM | E21: =IFERROR(__xludf.DUMMYFUNCTION("COUNTUNIQUEIFS(DailyActivity!B:B,DailyActivity!A:A,A21)"),31.0) -> 31
D22: =IF(B22<5000, "LOW",IF(B22<10000,"MEDIUM","HIGH")) -> MEDIUM | E22: =IFERROR(__xludf.DUMMYFUNCTION("COUNTUNIQUEIFS(DailyActivity!B:B,DailyActivity!A:A,A22)"),30.0) -> 30
D23: =IF(B23<5000, "LOW",IF(B23<10000,"MEDIUM","HIGH")) -> MEDIUM | E23: =IFERROR(__xludf.DUMMYFUNCTION("COUNTUNIQUEIFS(DailyActivity!B:B,DailyActivity!A:A,A23)"),28.0) -> 28
D24: =IF(B24<5000, "LOW",IF(B24<10000,"MEDIUM","HIGH")) -> MEDIUM | E24: =IFERROR(__xludf.DUMMYFUNCTION("COUNTUNIQUEIFS(DailyActivity!B:B,DailyActivity!A:A,A24)"),29.0) -> 29
D25: =IF(B25<5000, "LOW",IF(B25<10000,"MEDIUM","HIGH")) -> LOW | E25: =IFERROR(__xludf.DUMMYFUNCTION("COUNTUNIQUEIFS(DailyActivity!B:B,DailyActivity!A:A,A25)"),26.0) -> 26
D26: =IF(B26<5000, "LOW",IF(B26<10000,"MEDIUM","HIGH")) -> MEDIUM | E26: =IFERROR(__xludf.DUMMYFUNCTION("COUNTUNIQUEIFS(DailyActivity!B:B,DailyActivity!A:A,A26)"),31.0) -> 31
D27: =IF(B27<5000, "LOW",IF(B27<10000,"MEDIUM","HIGH")) -> HIGH | E27: =IFERROR(__xludf.DUMMYFUNCTION("COUNTUNIQUEIFS(DailyActivity!B:B,DailyActivity!A:A,A27)"),26.0) -> 26
D28: =IF(B28<5000, "LOW",IF(B28<10000,"MEDIUM","HIGH")) -> MEDIUM | E28: =IFERROR(__xludf.DUMMYFUNCTION("COUNTUNIQUEIFS(DailyActivity!B:B,DailyActivity!A:A,A28)"),31.0) -> 31
D29: =IF(B29<5000, "LOW",IF(B29<10000,"MEDIUM","HIGH")) -> HIGH | E29: =IFERROR(__xludf.DUMMYFUNCTION("COUNTUNIQUEIFS(DailyActivity!B:B,DailyActivity!A:A,A29)"),31.0) -> 31
D30: =IF(B30<5000, "LOW",IF(B30<10000,"MEDIUM","HIGH")) -> MEDIUM | E30: =IFERROR(__xludf.DUMMYFUNCTION("COUNTUNIQUEIFS(DailyActivity!B:B,DailyActivity!A:A,A30)"),19.0) -> 19
D31: =IF(B31<5000, "LOW",IF(B31<10000,"MEDIUM","HIGH")) -> MEDIUM | E31: =IFERROR(__xludf.DUMMYFUNCTION("COUNTUNIQUEIFS(DailyActivity!B:B,DailyActivity!A:A,A31)"),31.0) -> 31
D32: =IF(B32<5000, "LOW",IF(B32<10000,"MEDIUM","HIGH")) -> MEDIUM | E32: =IFERROR(__xludf.DUMMYFUNCTION("COUNTUNIQUEIFS(DailyActivity!B:B,DailyActivity!A:A,A32)"),31.0) -> 31
D33: =IF(B33<5000, "LOW",IF(B33<10000,"MEDIUM","HIGH")) -> LOW | E33: =IFERROR(__xludf.DUMMYFUNCTION("COUNTUNIQUEIFS(DailyActivity!B:B,DailyActivity!A:A,A33)"),29.0) -> 29
D34: =IF(B34<5000, "LOW",IF(B34<10000,"MEDIUM","HIGH")) -> HIGH | E34: =IFERROR(__xludf.DUMMYFUNCTION("COUNTUNIQUEIFS(DailyActivity!B:B,DailyActivity!A:A,A34)"),31.0) -> 31

Sheet Activity vs Sleep
A1: Id | B1: ActivityDate | C1: Uniqe ID | D1: TotalSteps | E1: Activity Level | F1: TotalSleepHours | G1: SleepEfficiency
A2: 1503960366 | B2: 42472 | C2: =CONCAT(A2,B2) -> 150396036642472 | D2: 13162 | E2: =IF(D2<5000, "LOW",IF(D2<10000,"MEDIUM","HIGH")) -> HIGH | F2: =VLOOKUP(C2,Sleep!C:F,4,FALSE) -> 0.22708333 | G2: =VLOOKUP(C2,Sleep!C:I,7,FALSE) -> 0.94508671
A3: 1503960366 | B3: 42473 | C3: =CONCAT(A3,B3) -> 150396036642473 | D3: 10735 | E3: =IF(D3<5000, "LOW",IF(D3<10000,"MEDIUM","HIGH")) -> HIGH | F3: =VLOOKUP(C3,Sleep!C:F,4,FALSE) -> 0.26666667 | G3: =VLOOKUP(C3,Sleep!C:I,7,FALSE) -> 0.94348894
A4: 1503960366 | B4: 42474 | C4: =CONCAT(A4,B4) -> 150396036642474 | D4: 10460 | F4: =VLOOKUP(C4,Sleep!C:F,4,FALSE) -> #N/A
A5: 1503960366 | B5: 42475 | C5: =CONCAT(A5,B5) -> 150396036642475 | D5: 9762 | E5: =IF(D5<5000, "LOW",IF(D5<10000,"MEDIUM","HIGH")) -> MEDIUM | F5: =VLOOKUP(C5,Sleep!C:F,4,FALSE) -> 0.28611111 | G5: =VLOOKUP(C5,Sleep!C:I,7,FALSE) -> 0.9321267
A6: 1503960366 | B6: 42476 | C6: =CONCAT(A6,B6) -> 150396036642476 | D6: 12669 | E6: =IF(D6<5000, "LOW",IF(D6<10000,"MEDIUM","HIGH")) -> HIGH | F6: =VLOOKUP(C6,Sleep!C:F,4,FALSE) -> 0.23611111 | G6: =VLOOKUP(C6,Sleep!C:I,7,FALSE) -> 0.92643052
A7: 1503960366 | B7: 42477 | C7: =CONCAT(A7,B7) -> 150396036642477 | D7: 9705 | E7: =IF(D7<5000, "LOW",IF(D7<10000,"MEDIUM","HIGH")) -> MEDIUM | F7: =VLOOKUP(C7,Sleep!C:F,4,FALSE) -> 0.48611111 | G7: =VLOOKUP(C7,Sleep!C:I,7,FALSE) -> 0.98314607
A8: 1503960366 | B8: 42478 | C8: =CONCAT(A8,B8) -> 150396036642478 | D8: 13019 | F8: =VLOOKUP(C8,Sleep!C:F,4,FALSE) -> #N/A
A9: 1503960366 | B9: 42479 | C9: =CONCAT(A9,B9) -> 150396036642479 | D9: 15506 | E9: =IF(D9<5000, "LOW",IF(D9<10000,"MEDIUM","HIGH")) -> HIGH | F9: =VLOOKUP(C9,Sleep!C:F,4,FALSE) -> 0.21111111 | G9: =VLOOKUP(C9,Sleep!C:I,7,FALSE) -> 0.95
A10: 1503960366 | B10: 42480 | C10: =CONCAT(A10,B10) -> 150396036642480 | D10: 10544 | E10: =IF(D10<5000, "LOW",IF(D10<10000,"MEDIUM","HIGH")) -> HIGH | F10: =VLOOKUP(C10,Sleep!C:F,4,FALSE) -> 0.25 | G10: =VLOOKUP(C10,Sleep!C:I,7,FALSE) -> 0.95490716
A11: 1503960366 | B11: 42481 | C11: =CONCAT(A11,B11) -> 150396036642481 | D11: 9819 | E11: =IF(D11<5000, "LOW",IF(D11<10000,"MEDIUM","HIGH")) -> MEDIUM | F11: =VLOOKUP(C11,Sleep!C:F,4,FALSE) -> 0.22569444 | G11: =VLOOKUP(C11,Sleep!C:I,7,FALSE) -> 0.89285714
A12: 1503960366 | B12: 42482 | C12: =CONCAT(A12,B12) -> 150396036642482 | D12: 12764 | F12: =VLOOKUP(C12,Sleep!C:F,4,FALSE) -> #N/A
A13: 1503960366 | B13: 42483 | C13: =CONCAT(A13,B13) -> 150396036642483 | D13: 14371 | E13: =IF(D13<5000, "LOW",IF(D13<10000,"MEDIUM","HIGH")) -> HIGH | F13: =VLOOKUP(C13,Sleep!C:F,4,FALSE) -> 0.25069444 | G13: =VLOOKUP(C13,Sleep!C:I,7,FALSE) -> 0.94010417
A14: 1503960366 | B14: 42484 | C14: =CONCAT(A14,B14) -> 150396036642484 | D14: 10039 | E14: =IF(D14<5000, "LOW",IF(D14<10000,"MEDIUM","HIGH")) -> HIGH | F14: =VLOOKUP(C14,Sleep!C:F,4,FALSE) -> 0.29861111 | G14: =VLOOKUP(C14,Sleep!C:I,7,FALSE) -> 0.95768374
A15: 1503960366 | B15: 42485 | C15: =CONCAT(A15,B15) -> 150396036642485 | D15: 15355 | E15: =IF(D15<5000, "LOW",IF(D15<10000,"MEDIUM","HIGH")) -> HIGH | F15: =VLOOKUP(C15,Sleep!C:F,4,FALSE) -> 0.19236111 | G15: =VLOOKUP(C15,Sleep!C:I,7,FALSE) -> 0.85758514
A16: 1503960366 | B16: 42486 | C16: =CONCAT(A16,B16) -> 150396036642486 | D16: 13755 | E16: =IF(D16<5000, "LOW",IF(D16<10000,"MEDIUM","HIGH")) -> HIGH | F16: =VLOOKUP(C16,Sleep!C:F,4,FALSE) -> 0.17013889 | G16: =VLOOKUP(C16,Sleep!C:I,7,FALSE) -> 0.89416058
A17: 1503960366 | B17: 42487 | C17: =CONCAT(A17,B17) -> 150396036642487 | D17: 18134 | F17: =VLOOKUP(C17,Sleep!C:F,4,FALSE) -> #N/A
A18: 1503960366 | B18: 42488 | C18: =CONCAT(A18,B18) -> 150396036642488 | D18: 13154 | E18: =IF(D18<5000, "LOW",IF(D18<10000,"MEDIUM","HIGH")) -> HIGH | F18: =VLOOKUP(C18,Sleep!C:F,4,FALSE) -> 0.25416667 | G18: =VLOOKUP(C18,Sleep!C:I,7,FALSE) -> 0.93129771
A19: 1503960366 | B19: 42489 | C19: =CONCAT(A19,B19) -> 150396036642489 | D19: 11181 | E19: =IF(D19<5000, "LOW",IF(D19<10000,"MEDIUM","HIGH")) -> HIGH | F19: =VLOOKUP(C19,Sleep!C:F,4,FALSE) -> 0.23680556 | G19: =VLOOKUP(C19,Sleep!C:I,7,FALSE) -> 0.96327684
A20: 1503960366 | B20: 42490 | C20: =CONCAT(A20,B20) -> 150396036642490 | D20: 14673 | E20: =IF(D20<5000, "LOW",IF(D20<10000,"MEDIUM","HIGH")) -> HIGH | F20: =VLOOKUP(C20,Sleep!C:F,4,FALSE) -> 0.28055556 | G20: =VLOOKUP(C20,Sleep!C:I,7,FALSE) -> 0.95058824
A21: 1503960366 | B21: 42491 | C21: =CONCAT(A21,B21) -> 150396036642491 | D21: 10602 | E21: =IF(D21<5000, "LOW",IF(D21<10000,"MEDIUM","HIGH")) -> HIGH | F21: =VLOOKUP(C21,Sleep!C:F,4,FALSE) -> 0.25625 | G21: =VLOOKUP(C21,Sleep!C:I,7,FALSE) -> 0.93181818
A22: 1503960366 | B22: 42492 | C22: =CONCAT(A22,B22) -> 150396036642492 | D22: 14727 | E22: =IF(D22<5000, "LOW",IF(D22<10000,"MEDIUM","HIGH")) -> HIGH | F22: =VLOOKUP(C22,Sleep!C:F,4,FALSE) -> 0.19236111 | G22: =VLOOKUP(C22,Sleep!C:I,7,FALSE) -> 0.89644013
A23: 1503960366 | B23: 42493 | C23: =CONCAT(A23,B23) -> 150396036642493 | D23: 15103 | E23: =IF(D23<5000, "LOW",IF(D23<10000,"MEDIUM","HIGH")) -> HIGH | F23: =VLOOKUP(C23,Sleep!C:F,4,FALSE) -> 0.18958333 | G23: =VLOOKUP(C23,Sleep!C:I,7,FALSE) -> 0.9222973
A24: 1503960366 | B24: 42494 | C24: =CONCAT(A24,B24) -> 150396036642494 | D24: 11100 | F24: =VLOOKUP(C24,Sleep!C:F,4,FALSE) -> #N/A
A25: 1503960366 | B25: 42495 | C25: =CONCAT(A25,B25) -> 150396036642495 | D25: 14070 | E25: =IF(D25<5000, "LOW",IF(D25<10000,"MEDIUM","HIGH")) -> HIGH | F25: =VLOOKUP(C25,Sleep!C:F,4,FALSE) -> 0.17152778 | G25: =VLOOKUP(C25,Sleep!C:I,7,FALSE) -> 0.93560606
A26: 1503960366 | B26: 42496 | C26: =CONCAT(A26,B26) -> 150396036642496 | D26: 12159 | E26: =IF(D26<5000, "LOW",IF(D26<10000,"MEDIUM","HIGH")) -> HIGH | F26: =VLOOKUP(C26,Sleep!C:F,4,FALSE) -> 0.23194444 | G26: =VLOOKUP(C26,Sleep!C:I,7,FALSE) -> 0.91008174
A27: 1503960366 | B27: 42497 | C27: =CONCAT(A27,B27) -> 150396036642497 | D27: 11992 | E27: =IF(D27<5000, "LOW",IF(D27<10000,"MEDIUM","HIGH")) -> HIGH | F27: =VLOOKUP(C27,Sleep!C:F,4,FALSE) -> 0.22986111 | G27: =VLOOKUP(C27,Sleep!C:I,7,FALSE) -> 0.94842407
A28: 1503960366 | B28: 42498 | C28: =CONCAT(A28,B28) -> 150396036642498 | D28: 10060 | E28: =IF(D28<5000, "LOW",IF(D28<10000,"MEDIUM","HIGH")) -> HIGH | F28: =VLOOKUP(C28,Sleep!C:F,4,FALSE) -> 0.4125 | G28: =VLOOKUP(C28,Sleep!C:I,7,FALSE) -> 0.97217676
A29: 1503960366 | B29: 42499 | C29: =CONCAT(A29,B29) -> 150396036642499 | D29: 12022 | E29: =IF(D29<5000, "LOW",IF(D29<10000,"MEDIUM","HIGH")) -> HIGH | F29: =VLOOKUP(C29,Sleep!C:F,4,FALSE) -> 0.23472222 | G29: =VLOOKUP(C29,Sleep!C:I,7,FALSE) -> 0.98830409
A30: 1503960366 | B30: 42500 | C30: =CONCAT(A30,B30) -> 150396036642500 | D30: 12207 | E30: =IF(D30<5000, "LOW",IF(D30<10000,"MEDIUM","HIGH")) -> HIGH | F30: =VLOOKUP(C30,Sleep!C:F,4,FALSE) -> 0.26597222 | G30: =VLOOKUP(C30,Sleep!C:I,7,FALSE) -> 0.95037221
A31: 1503960366 | B31: 42501 | C31: =CONCAT(A31,B31) -> 150396036642501 | D31: 12770 | E31: =IF(D31<5000, "LOW",IF(D31<10000,"MEDIUM","HIGH")) -> HIGH | F31: =VLOOKUP(C31,Sleep!C:F,4,FALSE) -> 0.19791667 | G31: =VLOOKUP(C31,Sleep!C:I,7,FALSE) -> 0.93137255
A32: 1503960366 | B32: 42502 | C32: =CONCAT(A32,B32) -> 150396036642502 | D32: 0 | F32: =VLOOKUP(C32,Sleep!C:F,4,FALSE) -> #N/A
A33: 1624580081 | B33: 42472 | C33: =CONCAT(A33,B33) -> 162458008142472 | D33: 8163 | F33: =VLOOKUP(C33,Sleep!C:F,4,FALSE) -> #N/A
A34: 1624580081 | B34: 42473 | C34: =CONCAT(A34,B34) -> 162458008142473 | D34: 7007 | F34: =VLOOKUP(C34,Sleep!C:F,4,FALSE) -> #N/A
A35: 1624580081 | B35: 42474 | C35: =CONCAT(A35,B35) -> 162458008142474 | D35: 9107 | F35: =VLOOKUP(C35,Sleep!C:F,4,FALSE) -> #N/A
A36: 1624580081 | B36: 42475 | C36: =CONCAT(A36,B36) -> 162458008142475 | D36: 1510 | F36: =VLOOKUP(C36,Sleep!C:F,4,FALSE) -> #N/A
A37: 1624580081 | B37: 42476 | C37: =CONCAT(A37,B37) -> 162458008142476 | D37: 5370 | F37: =VLOOKUP(C37,Sleep!C:F,4,FALSE) -> #N/A
A38: 1624580081 | B38: 42477 | C38: =CONCAT(A38,B38) -> 162458008142477 | D38: 6175 | F38: =VLOOKUP(C38,Sleep!C:F,4,FALSE) -> #N/A
A39: 1624580081 | B39: 42478 | C39: =CONCAT(A39,B39) -> 162458008142478 | D39: 10536 | F39: =VLOOKUP(C39,Sleep!C:F,4,FALSE) -> #N/A
A40: 1624580081 | B40: 42479 | C40: =CONCAT(A40,B40) -> 162458008142479 | D40: 2916 | F40: =VLOOKUP(C40,Sleep!C:F,4,FALSE) -> #N/A
...
